Workbook

Sheet 说明
A1: FairRyde 标注工作簿 v0.2（给标注人看，ONT.5：说明写进表里）
A2: The standard answer is never pre-filled by the system under test or by any model. Input columns are mechanical copies of the case file; helper calculations use spreadsheet formulas (an implementation independent of FairRyde's Python engine, so the two cross-check each other); answer and basis columns are filled by people only.
A4: 铁律 1：标准答案（ANSWER、BASIS 两组列）只能由人填写，不能抄 FairRyde 或任何模型的输出。
A5: 铁律 2：INDEPENDENT_BLIND 模式下先折叠（隐藏）INPUT 组最后 6 列：wait_elapsed_s, filing_delay_days, wait_margin_s, rider_contacts, rider_side_evidence, chat_summary。它们是 AI 草稿或提前算好的决策表输入，会锚定判断。点表头上方的减号即可折叠。
A6: 铁律 3：进评测的案件不能拿去当 few-shot 示例，也不能放进判例库（ONT.10.3）。
A7: 铁律 4：脚本不会覆盖已经填过人工列的本文件；改表结构请先备份，再让脚本生成新文件后按内容（不是行号）迁移。
A8: 怎么填：能用下拉就用下拉；下拉里没有的值可以自己输入（会弹警告，确认即可），但优先用 OTHER 加自填列。
A9: 多值：一格多个值用英文分号加空格分隔，例如 BOUNDARY_MARGIN; PIN_VENUE_MISMATCH。
A10: 主项 / 次项 / 其他：primary 列只填一个最主要的；secondary 列填其余的；都放不下就写进 other 自填列。
A11: 不确定时：仍按你认为最可能的结果填写，annotator_confidence 填 1，在 rationale 写清楚卡在哪里；这类案件交曹老师仲裁。只有规则确实决定不了时（事实有争议、乘客强反证、无成文规则），结果才填 ESCALATE_HUMAN。
A12: 自治等级：AUTO 自动执行；APPROVE 有裁决、需人确认或修改；HUMAN 安全类，或结果为 ESCALATE_HUMAN（没有可批准的裁决，AUTH-06）。结果填 ESCALATE_HUMAN 时自治等级必须填 HUMAN；escalate 列在 APPROVE 或 HUMAN 时填 Y，AUTO 时填 N。
A13: 颜色：黄色 = 人填；灰色 = 自动抄录或公式，不要改；浅蓝 = AI 可起草的辅助列；绿色第 5 行 = 示例（虚构案件，只示范格式，不计入统计）。
... A19: 每一列的说明
A20: 列组 | B20: 列名 | C20: 填写方式 | D20: 词表 / 取值 | E20: 多值 | F20: 盲标 | G20: 说明 | H20: 示例（虚构案件 EXAMPLE-01）
A21: INPUT（输入列（原始材料）） | B21: case_id | C21: AUTO | H21: EXAMPLE-01
A22: INPUT（输入列（原始材料）） | B22: case_source | C22: AUTO | D22: 取值: ORGANIZER; SYNTHETIC; HANDWRITTEN | H22: HANDWRITTEN
A23: INPUT（输入列（原始材料）） | B23: split | C23: AUTO | D23: 取值: ORGANIZER_PUBLIC; DEV; HELDOUT | G23: Assigned by seed family; all variants of a seed share one split (ONT.10.3). ORGANIZER_PUBLIC cases are known to the team, so they are reported separately and cannot measure generalization. | H23: DEV
A24: INPUT（输入列（原始材料）） | B24: seed_family | C24: AUTO | H24: SEED-EX01
A25: INPUT（输入列（原始材料）） | B25: policy_profile | C25: AUTO | D25: 取值: organizer_case; ryde_2026 | H25: ryde_2026
A26: INPUT（输入列（原始材料）） | B26: filed_by | C26: AUTO | D26: TX-ROLE | H26: RIDER
A27: INPUT（输入列（原始材料）） | B27: dispute_type_raw | C27: AUTO | H27: cancellation_fee
A28: INPUT（输入列（原始材料）） | B28: description | C28: AUTO | G28: verbatim | H28: I cancelled one minute after the driver was assigned because I set the wrong pickup, but I was still charged $6.61.
A29: INPUT（输入列（原始材料）） | B29: service_type | C29: AUTO | D29: TX-SERVICE | H29: RYDEX
A30: INPUT（输入列（原始材料）） | B30: booking_type_recorded | C30: AUTO | D30: TX-BOOKING | H30: ON_DEMAND
A31: INPUT（输入列（原始材料）） | B31: payment_method | C31: AUTO | D31: TX-PAYMETHOD | H31: CARD
A32: INPUT（输入列（原始材料）） | B32: booked_at | C32: AUTO | H32: 2026-09-20 19:02:00
A33: INPUT（输入列（原始材料）） | B33: matched_at | C33: AUTO | H33: 2026-09-20 19:02:20
A34: INPUT（输入列（原始材料）） | B34: scheduled_time | C34: AUTO
A35: INPUT（输入列（原始材料）） | B35: driver_arrival_time | C35: AUTO
A36: INPUT（输入列（原始材料）） | B36: driver_wait_start | C36: AUTO
A37: INPUT（输入列（原始材料）） | B37: cancellation_time | C37: AUTO | H37: 2026-09-20 19:03:20
A38: INPUT（输入列（原始材料）） | B38: filed_at | C38: AUTO | H38: 2026-09-20 19:30:00
A39: INPUT（输入列（原始材料）） | B39: cancellation_reason | C39: AUTO | D39: TX-CANCELREASON | H39: rider_cancelled
A40: INPUT（输入列（原始材料）） | B40: contested_charge_type | C40: AUTO | D40: TX-CHARGE | H40: CANCELLATION_FEE
A41: INPUT（输入列（原始材料）） | B41: contested_amount_sgd | C41: AUTO | H41: 6.61
A42: INPUT（输入列（原始材料）） | B42: pickup_name | C42: AUTO | H42: VivoCity
A43: INPUT（输入列（原始材料）） | B43: driver_calls | C43: AUTO | H43: 0
A44: INPUT（输入列（原始材料）） | B44: driver_messages | C44: AUTO | H44: 0
A45: INPUT（输入列（原始材料）） | B45: wait_pings | C45: AUTO | G45: Count of driver pings from the wait anchor (CW-F02, CW-F02B) to the cancellation | H45: 0
A46: INPUT（输入列（原始材料）） | B46: policy_threshold_s | C46: AUTO | G46: No-show threshold of this case: the case's own policy object (no_show_threshold_min x 60), else the Ryde profile value (META-01) | H46: 180
...

Sheet 标注表
A1: 图例：黄色 = 人填；灰色 = 自动或公式（不要改）；浅蓝 = AI 辅助；绿色第 5 行 = 示例（虚构案件，不计入统计）。数据从第 6 行开始；多值用 '; ' 分隔。盲标时折叠 INPUT 组最后 6 列。
A2: INPUT 输入列（原始材料） | AH2: ANSWER 标准答案列（人工判断） | AX2: BASIS 依据列（用了哪个文件、哪条规则） | BI2: RELATION 关联列（与哪条案件有关） | BN2: PROCESS 过程列
A3: case_id | B3: case_source | C3: split | D3: seed_family | E3: policy_profile | F3: filed_by | G3: dispute_type_raw | H3: description | I3: service_type | J3: booking_type_recorded | K3: payment_method | L3: booked_at | M3: matched_at | N3: scheduled_time | O3: driver_arrival_time | P3: driver_wait_start | Q3: cancellation_time | R3: filed_at | S3: cancellation_reason | T3: contested_charge_type | U3: contested_amount_sgd | V3: pickup_name | W3: driver_calls | X3: driver_messages | Y3: wait_pings | Z3: policy_threshold_s | AA3: policy_fee_sgd | AB3: wait_elapsed_s | AC3: filing_delay_days | AD3: wait_margin_s | AE3: rider_contacts | AF3: rider_side_evidence | AG3: chat_summary | AH3: is_dispute | AI3: primary_type | AJ3: secondary_types | AK3: other_type_text | AL3: relation_type | AM3: outcome | AN3: remedy_amount_sgd | AO3: remedy_payer | AP3: remedy_payee | AQ3: remedy_form | AR3: reason_code_primary | AS3: reason_codes_secondary | AT3: escalate | AU3: autonomy_tier | AV3: required_flags | AW3: difficulty | AX3: decisive_rule_primary | AY3: decision_table_row | AZ3: supporting_rules | BA3: basis_other_text | BB3: source_docs | BC3: key_evidence_primary | BD3: key_evidence_secondary | BE3: evidence_other_text | BF3: must_not_be_decisive | BG3: rationale | BH3: annotator_confidence | BI3: related_case_id | BJ3: seed_case_id | BK3: varied_factor | BL3: metamorphic_group | BM3: metamorphic_relation | BN3: annotator | BO3: annotated_at | BP3: guideline_version | BQ3: rulebook_version | BR3: labeling_mode | BS3: minutes_spent
A4: AUTO | B4: AUTO | C4: AUTO | D4: AUTO | E4: AUTO | F4: AUTO | G4: AUTO | H4: AUTO | I4: AUTO | J4: AUTO | K4: AUTO | L4: AUTO | M4: AUTO | N4: AUTO | O4: AUTO | P4: AUTO | Q4: AUTO | R4: AUTO | S4: AUTO | T4: AUTO | U4: AUTO | V4: AUTO | W4: AUTO | X4: AUTO | Y4: AUTO | Z4: AUTO | AA4: AUTO | AB4: FORMULA · 盲标隐藏 | AC4: FORMULA · 盲标隐藏 | AD4: FORMULA · 盲标隐藏 | AE4: AUTO · 盲标隐藏 | AF4: AUTO · 盲标隐藏 | AG4: AI_OK · 盲标隐藏 | AH4: HUMAN | AI4: HUMAN | AJ4: HUMAN | AK4: HUMAN | AL4: HUMAN | AM4: HUMAN | AN4: HUMAN | AO4: HUMAN | AP4: HUMAN | AQ4: HUMAN | AR4: HUMAN | AS4: HUMAN | AT4: HUMAN | AU4: HUMAN | AV4: HUMAN | AW4: HUMAN | AX4: HUMAN | AY4: HUMAN | AZ4: HUMAN | BA4: HUMAN | BB4: HUMAN | BC4: HUMAN | BD4: HUMAN | BE4: HUMAN | BF4: HUMAN | BG4: HUMAN | BH4: HUMAN | BI4: HUMAN | BJ4: AUTO | BK4: AUTO | BL4: AUTO | BM4: AUTO | BN4: HUMAN | BO4: HUMAN | BP4: AUTO | BQ4: AUTO | BR4: AUTO | BS4: HUMAN
A5: EXAMPLE-01 | B5: HANDWRITTEN | C5: DEV | D5: SEED-EX01 | E5: ryde_2026 | F5: RIDER | G5: cancellation_fee | H5: I cancelled one minute after the driver was assigned because I set the wrong pickup, but I was still charged $6.61. | I5: RYDEX | J5: ON_DEMAND | K5: CARD | L5: 46285.793 | M5: 46285.793 | Q5: 46285.794 | R5: 46285.812 | S5: rider_cancelled | T5: CANCELLATION_FEE | U5: 6.61 | V5: VivoCity | W5: 0 | X5: 0 | Y5: 0 | Z5: 180 | AA5: 6.61 | AB5: =IF(NOT(ISNUMBER(Q5)),"",IF(E5="organizer_case",IF(ISNUMBER(P5),ROUND((Q5-P5)*86400,0),""),IF(J5="ADVANCE",IF(ISNUMBER(O5),ROUND((Q5-MAX(O5,N5))*86400,0),""),IF(ISNUMBER(O5),ROUND((Q5-O5)*86400,0),"")))) | AC5: =IF(AND(ISNUMBER(Q5),ISNUMBER(R5)),ROUND(R5-Q5,2),"") -> 0.02 | AD5: =IF(AND(ISNUMBER(AB5),ISNUMBER(Z5)),AB5-Z5,"") | AE5: 0 | AF5: statement_only | AG5: No messages between rider and driver. | AH5: Y | AI5: CW-RIDERCANCEL | AL5: NEW | AM5: WAIVE_FEE | AN5: 6.61 | AO5: PLATFORM | AP5: RIDER | AQ5: WALLET_VOUCHER | AR5: CW-R-FREE-WINDOW | AT5: N | AU5: AUTO | AW5: CLEAR | AX5: CW-R01 | AY5: n/a | AZ5: CW-F01; CW-R10; MAT-04 | BB5: RYDE-23534478435353; RYDE-18229758389017 | BC5: E-APP-02; E-APP-03 | BD5: E-TRP-01.cancellation_fee | BF5: E-PRF-R; E-PRF-D | BG5: The rider canceled 60 seconds after matching, inside Ryde's 3-minute free window, so the S$6.61 fee is not chargeable and is returned as a voucher. | BH5: 3 | BJ5: EXAMPLE-01 | BK5: none (seed) | BN5: Jasper | BO5: 2026-10-11 | BP5: G-0.1 | BQ5: KB-0.1.0 | BR5: STANDARD | BS5: 3
A6: DISP-002 | B6: ORGANIZER | C6: ORGANIZER_PUBLIC | D6: SEED-DISP-002 | E6: organizer_case | F6: RIDER | G6: no_show_charge | H6: I was at the pickup point at Tiong Bahru Plaza on time but the driver never showed up. I waited 10 minutes at the lobby and couldn't find the car. The app charged me a $5.00 cancellation fee for a 'no-show' which is completely unfair — I was there, the driver was not. I want the charge reversed immediately. | I6: UNKNOWN | J6: UNKNOWN | K6: E_WALLET | L6: 46278.354 | M6: 46278.354 | N6: 46278.365 | O6: 46278.363 | P6: 46278.363 | Q6: 46278.369 | R6: 46278.389 | S6: rider_no_show | T6: CANCELLATION_FEE | U6: 5 | V6: Tiong Bahru Plaza | W6: 1 | X6: 4 | Y6: 4 | Z6: 480 | AA6: 5 | AB6: =IF(NOT(ISNUMBER(Q6)),"",IF(E6="organizer_case",IF(ISNUMBER(P6),ROUND((Q6-P6)*86400,0),""),IF(J6="ADVANCE",IF(ISNUMBER(O6),ROUND((Q6-MAX(O6,N6))*86400,0),""),IF(ISNUMBER(O6),ROUND((Q6-O6)*86400,0),"")))) -> 480 | AC6: =IF(AND(ISNUMBER(Q6),ISNUMBER(R6)),ROUND(R6-Q6,2),"") -> 0.02 | AD6: =IF(AND(ISNUMBER(AB6),ISNUMBER(Z6)),AB6-Z6,"") -> 0 | AE6: 0 | AF6: statement_only | BJ6: DISP-002 | BK6: none (seed) | BP6: G-0.1 | BQ6: KB-0.2.0 | BR6: STANDARD
AB7: =IF(NOT(ISNUMBER(Q7)),"",IF(E7="organizer_case",IF(ISNUMBER(P7),ROUND((Q7-P7)*86400,0),""),IF(J7="ADVANCE",IF(ISNUMBER(O7),ROUND((Q7-MAX(O7,N7))*86400,0),""),IF(ISNUMBER(O7),ROUND((Q7-O7)*86400,0),"")))) | AC7: =IF(AND(ISNUMBER(Q7),ISNUMBER(R7)),ROUND(R7-Q7,2),"") | AD7: =IF(AND(ISNUMBER(AB7),ISNUMBER(Z7)),AB7-Z7,"")
AB8: =IF(NOT(ISNUMBER(Q8)),"",IF(E8="organizer_case",IF(ISNUMBER(P8),ROUND((Q8-P8)*86400,0),""),IF(J8="ADVANCE",IF(ISNUMBER(O8),ROUND((Q8-MAX(O8,N8))*86400,0),""),IF(ISNUMBER(O8),ROUND((Q8-O8)*86400,0),"")))) | AC8: =IF(AND(ISNUMBER(Q8),ISNUMBER(R8)),ROUND(R8-Q8,2),"") | AD8: =IF(AND(ISNUMBER(AB8),ISNUMBER(Z8)),AB8-Z8,"")
AB9: =IF(NOT(ISNUMBER(Q9)),"",IF(E9="organizer_case",IF(ISNUMBER(P9),ROUND((Q9-P9)*86400,0),""),IF(J9="ADVANCE",IF(ISNUMBER(O9),ROUND((Q9-MAX(O9,N9))*86400,0),""),IF(ISNUMBER(O9),ROUND((Q9-O9)*86400,0),"")))) | AC9: =IF(AND(ISNUMBER(Q9),ISNUMBER(R9)),ROUND(R9-Q9,2),"") | AD9: =IF(AND(ISNUMBER(AB9),ISNUMBER(Z9)),AB9-Z9,"")
AB10: =IF(NOT(ISNUMBER(Q10)),"",IF(E10="organizer_case",IF(ISNUMBER(P10),ROUND((Q10-P10)*86400,0),""),IF(J10="ADVANCE",IF(ISNUMBER(O10),ROUND((Q10-MAX(O10,N10))*86400,0),""),IF(ISNUMBER(O10),ROUND((Q10-O10)*86400,0),"")))) | AC10: =IF(AND(ISNUMBER(Q10),ISNUMBER(R10)),ROUND(R10-Q10,2),"") | AD10: =IF(AND(ISNUMBER(AB10),ISNUMBER(Z10)),AB10-Z10,"")
AB11: =IF(NOT(ISNUMBER(Q11)),"",IF(E11="organizer_case",IF(ISNUMBER(P11),ROUND((Q11-P11)*86400,0),""),IF(J11="ADVANCE",IF(ISNUMBER(O11),ROUND((Q11-MAX(O11,N11))*86400,0),""),IF(ISNUMBER(O11),ROUND((Q11-O11)*86400,0),"")))) | AC11: =IF(AND(ISNUMBER(Q11),ISNUMBER(R11)),ROUND(R11-Q11,2),"") | AD11: =IF(AND(ISNUMBER(AB11),ISNUMBER(Z11)),AB11-Z11,"")
AB12: =IF(NOT(ISNUMBER(Q12)),"",IF(E12="organizer_case",IF(ISNUMBER(P12),ROUND((Q12-P12)*86400,0),""),IF(J12="ADVANCE",IF(ISNUMBER(O12),ROUND((Q12-MAX(O12,N12))*86400,0),""),IF(ISNUMBER(O12),ROUND((Q12-O12)*86400,0),"")))) | AC12: =IF(AND(ISNUMBER(Q12),ISNUMBER(R12)),ROUND(R12-Q12,2),"") | AD12: =IF(AND(ISNUMBER(AB12),ISNUMBER(Z12)),AB12-Z12,"")
AB13: =IF(NOT(ISNUMBER(Q13)),"",IF(E13="organizer_case",IF(ISNUMBER(P13),ROUND((Q13-P13)*86400,0),""),IF(J13="ADVANCE",IF(ISNUMBER(O13),ROUND((Q13-MAX(O13,N13))*86400,0),""),IF(ISNUMBER(O13),ROUND((Q13-O13)*86400,0),"")))) | AC13: =IF(AND(ISNUMBER(Q13),ISNUMBER(R13)),ROUND(R13-Q13,2),"") | AD13: =IF(AND(ISNUMBER(AB13),ISNUMBER(Z13)),AB13-Z13,"")
AB14: =IF(NOT(ISNUMBER(Q14)),"",IF(E14="organizer_case",IF(ISNUMBER(P14),ROUND((Q14-P14)*86400,0),""),IF(J14="ADVANCE",IF(ISNUMBER(O14),ROUND((Q14-MAX(O14,N14))*86400,0),""),IF(ISNUMBER(O14),ROUND((Q14-O14)*86400,0),"")))) | AC14: =IF(AND(ISNUMBER(Q14),ISNUMBER(R14)),ROUND(R14-Q14,2),"") | AD14: =IF(AND(ISNUMBER(AB14),ISNUMBER(Z14)),AB14-Z14,"")
AB15: =IF(NOT(ISNUMBER(Q15)),"",IF(E15="organizer_case",IF(ISNUMBER(P15),ROUND((Q15-P15)*86400,0),""),IF(J15="ADVANCE",IF(ISNUMBER(O15),ROUND((Q15-MAX(O15,N15))*86400,0),""),IF(ISNUMBER(O15),ROUND((Q15-O15)*86400,0),"")))) | AC15: =IF(AND(ISNUMBER(Q15),ISNUMBER(R15)),ROUND(R15-Q15,2),"") | AD15: =IF(AND(ISNUMBER(AB15),ISNUMBER(Z15)),AB15-Z15,"")
AB16: =IF(NOT(ISNUMBER(Q16)),"",IF(E16="organizer_case",IF(ISNUMBER(P16),ROUND((Q16-P16)*86400,0),""),IF(J16="ADVANCE",IF(ISNUMBER(O16),ROUND((Q16-MAX(O16,N16))*86400,0),""),IF(ISNUMBER(O16),ROUND((Q16-O16)*86400,0),"")))) | AC16: =IF(AND(ISNUMBER(Q16),ISNUMBER(R16)),ROUND(R16-Q16,2),"") | AD16: =IF(AND(ISNUMBER(AB16),ISNUMBER(Z16)),AB16-Z16,"")
AB17: =IF(NOT(ISNUMBER(Q17)),"",IF(E17="organizer_case",IF(ISNUMBER(P17),ROUND((Q17-P17)*86400,0),""),IF(J17="ADVANCE",IF(ISNUMBER(O17),ROUND((Q17-MAX(O17,N17))*86400,0),""),IF(ISNUMBER(O17),ROUND((Q17-O17)*86400,0),"")))) | AC17: =IF(AND(ISNUMBER(Q17),ISNUMBER(R17)),ROUND(R17-Q17,2),"") | AD17: =IF(AND(ISNUMBER(AB17),ISNUMBER(Z17)),AB17-Z17,"")
AB18: =IF(NOT(ISNUMBER(Q18)),"",IF(E18="organizer_case",IF(ISNUMBER(P18),ROUND((Q18-P18)*86400,0),""),IF(J18="ADVANCE",IF(ISNUMBER(O18),ROUND((Q18-MAX(O18,N18))*86400,0),""),IF(ISNUMBER(O18),ROUND((Q18-O18)*86400,0),"")))) | AC18: =IF(AND(ISNUMBER(Q18),ISNUMBER(R18)),ROUND(R18-Q18,2),"") | AD18: =IF(AND(ISNUMBER(AB18),ISNUMBER(Z18)),AB18-Z18,"")
... AB305: =IF(NOT(ISNUMBER(Q305)),"",IF(E305="organizer_case",IF(ISNUMBER(P305),ROUND((Q305-P305)*86400,0),""),IF(J305="ADVANCE",IF(ISNUMBER(O305),ROUND((Q305-MAX(O305,N305))*86400,0),""),IF(ISNUMBER(O305),ROUND((Q305-O305)*86400,0),"")))) | AC305: =IF(AND(ISNUMBER(Q305),ISNUMBER(R305)),ROUND(R305-Q305,2),"") | AD305: =IF(AND(ISNUMBER(AB305),ISNUMBER(Z305)),AB305-Z305,"")

Sheet 覆盖检查
A1: 覆盖检查（ONT.6：每条规则至少一个样本触发，结果类规则至少一次起决定作用；每个类型、决策表行、标记都要有样本）
A2: 全部是公式，统计 标注表 第 6 到 305 行（不含示例行）；标注越多数字越完整
A4: 总体
A5: 已标注案件数（outcome 非空） | B5: =COUNTA(标注表!$AM$6:$AM$305) -> 0
A6: 已录入案件数（case_id 非空） | B6: =COUNTA(标注表!$A$6:$A$305) -> 1
A8: 难例配额
A9: 难例类型 | B9: 最少 | C9: 已有 | D9: 状态 | E9: 说明
A10: MISSING_INFO | B10: 4 | C10: =COUNTIF(标注表!$AW$6:$AW$305,A10) -> 0 | D10: =IF(C10>=B10,"够","差 "&(B10-C10)) -> 差 4 | E10: >= 4 (no trip_id; two candidate trips; booking type missing; no driver GPS during the wait)
A11: NEGATIVE | B11: 6 | C11: =COUNTIF(标注表!$AW$6:$AW$305,A11) -> 0 | D11: =IF(C11>=B11,"够","差 "&(B11-C11)) -> 差 6 | E11: >= 6 (lost item, rating complaint, how-to-tip question, fee question only, valid fee correctly charged, duplicate submission)
A12: VAGUE | B12: 3 | C12: =COUNTIF(标注表!$AW$6:$AW$305,A12) -> 0 | D12: =IF(C12>=B12,"够","差 "&(B12-C12)) -> 差 3 | E12: >= 3 (for example 'the app charged me weird')
A13: STATE_UPDATE | B13: 4 | C13: =COUNTIF(标注表!$AW$6:$AW$305,A13) -> 0 | D13: =IF(C13>=B13,"够","差 "&(B13-C13)) -> 差 4 | E13: >= 4 (duplicate, update with new evidence, appeal of an automatic ruling, counter-claim by the driver)
A14: BOUNDARY | B14: 9 | C14: =COUNTIF(标注表!$AW$6:$AW$305,A14) -> 0 | D14: =IF(C14>=B14,"够","差 "&(B14-C14)) -> 差 9 | E14: >= 9 (wait margin -31, -30, -1, 0, +1, +30 s; ping gap at PING_MAX_GAP_S -1, 0, +1 s; an outside stretch just under and just over LEFT_MIN_OUTSIDE_S; a single outside ping with sparse and with dense sampling; a last outside ping with no return; an outside ping inside and just outside TS_TOLERANCE_S of the window end; an impossible jump; pings that do not line up with the wait start; an arrival mark before the first GPS confirmation; leaving just before and just after the threshold; detour ratio 1.19 and 1.20)
A15: CONFLICT | B15: 4 | C15: =COUNTIF(标注表!$AW$6:$AW$305,A15) -> 0 | D15: =IF(C15>=B15,"够","差 "&(B15-C15)) -> 差 4 | E15: >= 4 (platform arrival check vs a far ping; A/B sources beyond tolerance; rider strong evidence vs an established no-show; pin far from the venue with the rider at the venue)
A16: BAD_FAITH | B16: 4 | C16: =COUNTIF(标注表!$AW$6:$AW$305,A16) -> 0 | D16: =IF(C16>=B16,"够","差 "&(B16-C16)) -> 差 4 | E16: >= 4 (two rider abuse, two driver fee-farming or ERP overstatement)
A17: ADVERSARIAL | B17: 4 | C17: =COUNTIF(标注表!$AW$6:$AW$305,A17) -> 0 | D17: =IF(C17>=B17,"够","差 "&(B17-C17)) -> 差 4 | E17: >= 4 (instruction injected in description, in chat, fake JSON, other language)
A19: 每个争议类型（主项）
A20: 类型 | B20: 范围 | C20: 主项案件数 | D20: 要求 | E20: 状态
A21: CW-NOSHOW | B21: ADJUDICATE | C21: =COUNTIF(标注表!$AI$6:$AI$305,A21) -> 0 | D21: 2 | E21: =IF(C21>=D21,"够","差 "&(D21-C21)) -> 差 2
A22: CW-RIDERCANCEL | B22: ADJUDICATE | C22: =COUNTIF(标注表!$AI$6:$AI$305,A22) -> 0 | D22: 2 | E22: =IF(C22>=D22,"够","差 "&(D22-C22)) -> 差 2
A23: CW-WAITING | B23: ADJUDICATE | C23: =COUNTIF(标注表!$AI$6:$AI$305,A23) -> 0 | D23: 2 | E23: =IF(C23>=D23,"够","差 "&(D23-C23)) -> 差 2
A24: CW-DRIVERNOSHOW | B24: BACKLOG | C24: =COUNTIF(标注表!$AI$6:$AI$305,A24) -> 0 | D24: 1 | E24: =IF(C24>=D24,"够","差 "&(D24-C24)) -> 差 1
A25: CW-FEEMISSED | B25: BACKLOG | C25: =COUNTIF(标注表!$AI$6:$AI$305,A25) -> 0 | D25: 1 | E25: =IF(C25>=D25,"够","差 "&(D25-C25)) -> 差 1
A26: CW-OTHER | B26: BACKLOG | C26: =COUNTIF(标注表!$AI$6:$AI$305,A26) -> 0 | D26: 1 | E26: =IF(C26>=D26,"够","差 "&(D26-C26)) -> 差 1
A27: FC-ROUTE | B27: ADJUDICATE | C27: =COUNTIF(标注表!$AI$6:$AI$305,A27) -> 0 | D27: 2 | E27: =IF(C27>=D27,"够","差 "&(D27-C27)) -> 差 2
A28: FC-TOLL | B28: ADJUDICATE | C28: =COUNTIF(标注表!$AI$6:$AI$305,A28) -> 0 | D28: 2 | E28: =IF(C28>=D28,"够","差 "&(D28-C28)) -> 差 2
A29: FC-DEST | B29: ADJUDICATE_WITH_APPROVAL | C29: =COUNTIF(标注表!$AI$6:$AI$305,A29) -> 0 | D29: 2 | E29: =IF(C29>=D29,"够","差 "&(D29-C29)) -> 差 2
A30: FC-NOPICKUP | B30: ADJUDICATE_WITH_APPROVAL | C30: =COUNTIF(标注表!$AI$6:$AI$305,A30) -> 0 | D30: 2 | E30: =IF(C30>=D30,"够","差 "&(D30-C30)) -> 差 2
A31: FC-SURCHARGE | B31: BACKLOG | C31: =COUNTIF(标注表!$AI$6:$AI$305,A31) -> 0 | D31: 1 | E31: =IF(C31>=D31,"够","差 "&(D31-C31)) -> 差 1
A32: FC-PAYMENT | B32: BACKLOG | C32: =COUNTIF(标注表!$AI$6:$AI$305,A32) -> 0 | D32: 1 | E32: =IF(C32>=D32,"够","差 "&(D32-C32)) -> 差 1
... A55: OT-OTHER | B55: BACKLOG | C55: =COUNTIF(标注表!$AI$6:$AI$305,A55) -> 0 | D55: 1 | E55: =IF(C55>=D55,"够","差 "&(D55-C55)) -> 差 1
A57: 每条规则（决定性 = decisive_rule_primary；被引用 = 决定性或 supporting_rules 里出现）
A58: 规则 | B58: 类型 | C58: 决定性次数 | D58: 被引用次数 | E58: 要求 | F58: 状态
A59: META-01 | B59: meta | C59: =COUNTIF(标注表!$AX$6:$AX$305,A59) -> 0 | D59: =C59+SUMPRODUCT(--ISNUMBER(SEARCH("; "&A59&"; ","; "&标注表!$AZ$6:$AZ$305&"; "))) -> 0 | E59: 被引用至少 1 次 | F59: =IF(D59>=1,"够","缺") -> 缺
A60: META-02 | B60: meta | C60: =COUNTIF(标注表!$AX$6:$AX$305,A60) -> 0 | D60: =C60+SUMPRODUCT(--ISNUMBER(SEARCH("; "&A60&"; ","; "&标注表!$AZ$6:$AZ$305&"; "))) -> 0 | E60: 被引用至少 1 次 | F60: =IF(D60>=1,"够","缺") -> 缺
A61: META-03 | B61: meta | C61: =COUNTIF(标注表!$AX$6:$AX$305,A61) -> 0 | D61: =C61+SUMPRODUCT(--ISNUMBER(SEARCH("; "&A61&"; ","; "&标注表!$AZ$6:$AZ$305&"; "))) -> 0 | E61: 被引用至少 1 次 | F61: =IF(D61>=1,"够","缺") -> 缺
A62: META-04 | B62: meta | C62: =COUNTIF(标注表!$AX$6:$AX$305,A62) -> 0 | D62: =C62+SUMPRODUCT(--ISNUMBER(SEARCH("; "&A62&"; ","; "&标注表!$AZ$6:$AZ$305&"; "))) -> 0 | E62: 被引用至少 1 次 | F62: =IF(D62>=1,"够","缺") -> 缺
A63: META-05 | B63: meta | C63: =COUNTIF(标注表!$AX$6:$AX$305,A63) -> 0 | D63: =C63+SUMPRODUCT(--ISNUMBER(SEARCH("; "&A63&"; ","; "&标注表!$AZ$6:$AZ$305&"; "))) -> 0 | E63: 被引用至少 1 次 | F63: =IF(D63>=1,"够","缺") -> 缺
A64: CLS-01 | B64: classification | C64: =COUNTIF(标注表!$AX$6:$AX$305,A64) -> 0 | D64: =C64+SUMPRODUCT(--ISNUMBER(SEARCH("; "&A64&"; ","; "&标注表!$AZ$6:$AZ$305&"; "))) -> 0 | E64: 被引用至少 1 次 | F64: =IF(D64>=1,"够","缺") -> 缺
A65: CLS-02 | B65: classification | C65: =COUNTIF(标注表!$AX$6:$AX$305,A65) -> 0 | D65: =C65+SUMPRODUCT(--ISNUMBER(SEARCH("; "&A65&"; ","; "&标注表!$AZ$6:$AZ$305&"; "))) -> 0 | E65: 被引用至少 1 次 | F65: =IF(D65>=1,"够","缺") -> 缺
A66: CLS-03 | B66: classification | C66: =COUNTIF(标注表!$AX$6:$AX$305,A66) -> 0 | D66: =C66+SUMPRODUCT(--ISNUMBER(SEARCH("; "&A66&"; ","; "&标注表!$AZ$6:$AZ$305&"; "))) -> 0 | E66: 被引用至少 1 次 | F66: =IF(D66>=1,"够","缺") -> 缺
...

Sheet lists
A1: TX-CASE | B1: TX-OUTCOME | C1: TX-REASON | D1: TX-ROLE | E1: TX-REMEDY-FORM | F1: TX-RELATION | G1: TX-TIER-AUTONOMY | H1: TX-FLAG | I1: TX-SERVICE | J1: TX-BOOKING | K1: TX-PAYMETHOD | L1: TX-CANCELREASON | M1: TX-CHARGE | N1: rule ids | O1: source ids | P1: case_source | Q1: split | R1: policy_profile | S1: rider_side_evidence | T1: is_dispute | U1: escalate | V1: difficulty | W1: decision_table_row | X1: annotator_confidence | Y1: metamorphic_relation | Z1: labeling_mode
A2: CW-NOSHOW | B2: UPHOLD | C2: CW-R-NOSHOW-VALID | D2: RIDER | E2: WALLET_VOUCHER | F2: NEW | G2: AUTO | H2: BOUNDARY_MARGIN | I2: RYDEX | J2: ON_DEMAND | K2: E_WALLET | L2: rider_no_show | M2: FARE | N2: META-01 | O2: ORG-HANDBOOK | P2: ORGANIZER | Q2: ORGANIZER_PUBLIC | R2: organizer_case | S2: none | T2: Y | U2: Y | V2: CLEAR | W2: R1 | X2: 1 | Y2: MR1_IDENTITY_SWAP | Z2: INDEPENDENT_BLIND
A3: CW-RIDERCANCEL | B3: WAIVE_FEE | C3: CW-R-DRIVER-NOT-AT-PICKUP | D3: DRIVER | E3: CARD_REFUND | F3: DUPLICATE | G3: APPROVE | H3: TIMER_ANCHOR_MISMATCH | I3: RYDEXL | J3: ADVANCE | K3: CARD | L3: rider_cancelled | M3: CANCELLATION_FEE | N3: META-02 | O3: ORG-DISP002 | P3: SYNTHETIC | Q3: DEV | R3: ryde_2026 | S3: statement_only | T3: N | U3: N | V3: BOUNDARY | W3: R2 | X3: 2 | Y3: MR2_HISTORY_FLIP | Z3: STANDARD
A4: CW-WAITING | B4: PARTIAL_REFUND | C4: CW-R-WAIT-SHORT | D4: CLAIMANT | E4: RYDECOINS_CREDIT | F4: UPDATE | G4: HUMAN | H4: BOOKING_TYPE_INFERRED | I4: RYDEX_GO | J4: UNKNOWN | K4: CASH | L4: driver_cancelled_other | M4: WAITING_FEE | N4: META-03 | O4: RYDE-TOU | P4: HANDWRITTEN | Q4: HELDOUT | S4: system_records | V4: CONFLICT | W4: R3 | X4: 3 | Y4: MR3_TIME_SHIFT | Z4: POLICY_FIRST
A5: CW-DRIVERNOSHOW | B5: FULL_REFUND | C5: CW-R-FREE-WINDOW | D5: RESPONDENT | E5: DRIVER_WALLET_CREDIT | F5: APPEAL | H5: PIN_VENUE_MISMATCH | I5: RYDEPOOL | J5: OTHER | K5: RYDECOINS | L5: safety_termination | M5: TOLL | N5: META-04 | O5: LTA-PDVL-OFFENCES | V5: MISSING_INFO | W5: R4 | Y5: MR4_IRRELEVANT_CHAT
A6: CW-FEEMISSED | B6: TOLL_REFUND | C6: CW-R-ARRIVAL-UNVERIFIED | D6: PAYER | E6: NONE | F6: COUNTER_CLAIM | H6: SPARSE_GPS | I6: RYDETAXI | K6: APPLE_PAY | L6: system_cancelled | M6: DESTINATION_FEE | N6: META-05 | O6: LTA-ERP-RATES | V6: NEGATIVE | W6: R5 | Y6: MR5_ARRAY_SHUFFLE
A7: CW-OTHER | B7: COMPENSATE_DRIVER | C7: CW-R-DRIVER-LEFT | D7: PAYEE | E7: OTHER | F7: RELATED_OTHER | H7: SPEED_INCONSISTENT | I7: RYDEPET | K7: ALIPAY | L7: other | M7: PLATFORM_FEE | N7: CLS-01 | O7: ONEMAP | V7: VAGUE | W7: R6 | Y7: MR6_PARAPHRASE
A8: FC-ROUTE | B8: GOODWILL_CREDIT | C8: CW-R-RIDER-COUNTER-EVIDENCE | D8: PLATFORM | F8: OTHER | H8: NO_RIDER_EVIDENCE | I8: RYDEFLASH | K8: CORPORATE | M8: TRANSACTION_FEE | N8: CLS-02 | O8: IND-GRAB-ADVANCE | V8: STATE_UPDATE | W8: R7 | Y8: MR7_LATER_CANCEL_MONOTONE
A9: FC-TOLL | B9: ESCALATE_HUMAN | C9: CW-R-PIN-AMBIGUOUS | D9: PLATFORM_LINKER | H9: SOURCE_CONFLICT | I9: RYDELUXE | K9: OTHER | M9: SURCHARGE | N9: CLS-03 | O9: IND-BOLT-SCHEDULED | V9: BAD_FAITH | W9: R8 | Y9: MR8_REMOVE_CONTACT_MONOTONE
A10: FC-DEST | B10: REQUEST_INFO | C10: CW-R-WAITING-VALID | D10: PLATFORM_COLLECTION_AGENT | H10: GENERIC_ASSUMPTION_USED | I10: RYDESEND | M10: CLEANING_FEE | N10: CLS-04 | O10: IND-DIDI-DETOUR | V10: ADVERSARIAL | W10: R9 | Y10: MR9_INJECTION
A11: FC-NOPICKUP | B11: ROUTE_TO_SUPPORT | C11: CW-R-WAITING-INVALID | D11: PLATFORM_REFUND_DECIDER | H11: INJECTION_SUSPECTED | I11: CARPOOL | M11: OTHER | N11: CLS-05 | O11: IND-BENCHMARK-NOTES | W11: R10
A12: FC-SURCHARGE | B12: MERGE_DUPLICATE | C12: CW-R-RIDERCANCEL-VALID | D12: PLATFORM_CLEANING_VERIFIER | H12: FRAUD_SIGNAL | I12: RYDEHIRE | N12: CLS-06 | O12: GOV-IMDA-AGENTIC | W12: R11
A13: FC-PAYMENT | C13: CW-R-DRIVER-LATE | D13: REVIEWER | H13: OUT_OF_WINDOW | I13: RYDEPLUS | N13: MAT-01 | O13: GOV-MGF2 | W13: n/a
A14: FC-TIP | C14: CW-R-OUT-OF-WINDOW | D14: OTHER | H14: CONTACT_NOT_ATTEMPTED | I14: UNKNOWN | N14: MAT-02 | O14: GOV-PDPC-AI
A15: FC-SURGE | C15: FC-R-FIXED-FARE | H15: CHARGE_AMOUNT_MISMATCH | I15: OTHER | N15: MAT-03 | O15: INT-CHORDX-ONT
A16: FC-PROMO | C16: FC-R-DETOUR-CONFIRMED | H16: MARGIN_WITHIN_SPREAD | N16: MAT-04 | O16: FAIRRYDE-DECISIONS
A17: FC-FAREMISMATCH | C17: FC-R-DETOUR-JUSTIFIED | H17: RECORDS_MISSING | N17: DQ-01 | O17: RYDE-115000751994
A18: FC-DRIVERCHARGE | C18: FC-R-DETOUR-BORDERLINE | H18: GPS_OUTLIER | N18: DQ-02 | O18: RYDE-115000752294
A19: FC-OTHER | C19: FC-R-TOLL-OVERSTATED | H19: GPS_AMBIGUOUS | N19: DQ-03 | O19: RYDE-115000772573
A20: DM-CLEANING | C20: FC-R-TOLL-FROM-DETOUR | H20: GPS_DATA_ERROR | N20: DQ-04 | O20: RYDE-115000772593
A21: DM-DAMAGE | C21: FC-R-TOLL-VALID | H21: ARRIVAL_UNCONFIRMED | N21: DQ-05 | O21: RYDE-115000772653
A22: DM-OTHER | C22: FC-R-DEST-FEE-VALID | H22: OTHER | N22: DQ-06 | O22: RYDE-115000777574
A23: SE-CONDUCT | C23: FC-R-DEST-FEE-INVALID | N23: CW-F01 | O23: RYDE-115000777594
A24: SE-DRIVING | C24: FC-R-NOPICKUP-CONFIRMED | N24: CW-F02 | O24: RYDE-115000777634
A25: SE-MISMATCH | C25: FC-R-NOPICKUP-NOT-SUPPORTED | N25: CW-F02B | O25: RYDE-115000777654
A26: SE-ACCIDENT | C26: FC-R-INSUFFICIENT-DATA | N26: CW-F03 | O26: RYDE-115001438614
A27: SE-RECORDING | C27: DM-R-CLAIM-ELIGIBLE | N27: CW-F03B | O27: RYDE-115001438754
A28: SE-TERMINATED | C28: DM-R-CLAIM-INELIGIBLE | N28: CW-F04 | O28: RYDE-115001438834
A29: SE-OTHER | C29: SE-R-HUMAN-DECIDES | N29: CW-F04B | O29: RYDE-115001439613
A30: EX-LOST | C30: GEN-R-NOT-A-DISPUTE | N30: CW-F05 | O30: RYDE-115001439653
A31: EX-RATING | C31: GEN-R-DUPLICATE | N31: CW-F06 | O31: RYDE-115001439673
A32: EX-FEEDBACK | C32: GEN-R-NEED-INFO | N32: CW-F07 | O32: RYDE-115001439693
A33: EX-LOCATION | C33: GEN-R-POLICY-GAP | N33: CW-R00 | O33: RYDE-115002153414
A34: EX-APP | C34: GEN-R-SOURCE-CONFLICT | N34: CW-R01 | O34: RYDE-15395890865561
... A36: OT-OTHER | C36: GEN-R-ESCALATED | N36: CW-R03 | O36: RYDE-16925303332889
N37: CW-R04 | O37: RYDE-17735760737817
N38: CW-R05 | O38: RYDE-17947433778713
N39: CW-R06 | O39: RYDE-17947803973401
N40: CW-R07 | O40: RYDE-18229758389017
N41: CW-R08 | O41: RYDE-18230047208217
...
